<?xml version="1.0" encoding="utf-8"?>
<!-- This URDF was automatically created by SolidWorks to URDF Exporter! Originally created by Stephen Brawner (brawner@gmail.com) 
     Commit Version: 1.6.0-4-g7f85cfe  Build Version: 1.6.7995.38578
     For more information, please see http://wiki.ros.org/sw_urdf_exporter -->
<robot
  name="quad">
  <link
    name="body">
    <inertial>
      <origin
        xyz="0.0119136125020121 -0.0446594666650345 0.0624999999996797"
        rpy="0 0 0" />
      <mass
        value="2.38478530150357" />
      <inertia
        ixx="0.00598681030721035"
        ixy="2.63434309472512E-05"
        ixz="-9.01980987549905E-05"
        iyy="0.00728291695959716"
        iyz="-1.82080520289269E-17"
        izz="0.00302670062029109" />
    </inertial>
    <visual>
      <origin
        xyz="0 0 0"
        rpy="0 0 0" />
      <geometry>
        <mesh
          filename="package://quad/meshes/body.STL" />
      </geometry>
      <material
        name="">
        <color
          rgba="1 1 1 1" />
      </material>
    </visual>
    <collision>
      <origin
        xyz="0 0 0"
        rpy="0 0 0" />
      <geometry>
        <mesh
          filename="package://quad/meshes/body.STL" />
      </geometry>
    </collision>
  </link>
  <link
    name="fl_thigh">
    <inertial>
      <origin
        xyz="0.139292819513255 0.00235319440952292 -3.0577818958058E-06"
        rpy="0 0 0" />
      <mass
        value="0.32829098650712" />
      <inertia
        ixx="0.000112047683322158"
        ixy="-1.62097882949947E-05"
        ixz="2.09839269866338E-08"
        iyy="0.000847860163744953"
        iyz="5.16343563659286E-10"
        izz="0.000753244083618435" />
    </inertial>
    <visual>
      <origin
        xyz="0 0 0"
        rpy="0 0 0" />
      <geometry>
        <mesh
          filename="package://quad/meshes/fl_thigh.STL" />
      </geometry>
      <material
        name="">
        <color
          rgba="1 1 1 1" />
      </material>
    </visual>
    <collision>
      <origin
        xyz="0 0 0"
        rpy="0 0 0" />
      <geometry>
        <mesh
          filename="package://quad/meshes/fl_thigh.STL" />
      </geometry>
    </collision>
  </link>
  <joint
    name="fl_hip_roll"
    type="revolute">
    <origin
      xyz="0.063 0.055225 -0.04425"
      rpy="0 0 0" />
    <parent
      link="body" />
    <child
      link="fl_thigh" />
    <axis
      xyz="-1 0 0" />
    <limit
      lower="-12.56"
      upper="12.56"
      effort="10"
      velocity="250" />
  </joint>
  <link
    name="fl_calf">
    <inertial>
      <origin
        xyz="-2.7238911096128E-06 0.0780352358767988 -0.0778540126521879"
        rpy="0 0 0" />
      <mass
        value="0.369733221029888" />
      <inertia
        ixx="0.00111379811136972"
        ixy="4.53236441978577E-10"
        ixz="-2.08684607908445E-08"
        iyy="0.00120693430900378"
        iyz="8.65938367597369E-05"
        izz="0.000145627421326542" />
    </inertial>
    <visual>
      <origin
        xyz="0 0 0"
        rpy="0 0 0" />
      <geometry>
        <mesh
          filename="package://quad/meshes/fl_calf.STL" />
      </geometry>
      <material
        name="">
        <color
          rgba="1 1 1 1" />
      </material>
    </visual>
    <collision>
      <origin
        xyz="0 0 0"
        rpy="0 0 0" />
      <geometry>
        <mesh
          filename="package://quad/meshes/fl_calf.STL" />
      </geometry>
    </collision>
  </link>
  <joint
    name="fl_hip_pitch"
    type="revolute">
    <origin
      xyz="0.19925 -0.016 0"
      rpy="0 0 0" />
    <parent
      link="fl_thigh" />
    <child
      link="fl_calf" />
    <axis
      xyz="0 1 0" />
    <limit
      lower="-12.56"
      upper="12.56"
      effort="10"
      velocity="250" />
  </joint>
  <link
    name="fl_foot">
    <inertial>
      <origin
        xyz="-0.00181810973272556 0.0514205807877523 -0.0990956880947121"
        rpy="0 0 0" />
      <mass
        value="0.113203575524731" />
      <inertia
        ixx="0.000259844925102448"
        ixy="-2.89449189486509E-08"
        ixz="2.28109802667937E-06"
        iyy="0.000265395195240856"
        iyz="4.93150132283971E-06"
        izz="1.44096258097618E-05" />
    </inertial>
    <visual>
      <origin
        xyz="0 0 0"
        rpy="0 0 0" />
      <geometry>
        <mesh
          filename="package://quad/meshes/fl_foot.STL" />
      </geometry>
      <material
        name="">
        <color
          rgba="1 1 1 1" />
      </material>
    </visual>
    <collision>
      <origin
        xyz="0 0 0"
        rpy="0 0 0" />
      <geometry>
        <mesh
          filename="package://quad/meshes/fl_foot.STL" />
      </geometry>
    </collision>
  </link>
  <joint
    name="fl_knee_pitch"
    type="revolute">
    <origin
      xyz="0 0.063 -0.15625"
      rpy="0 0 0" />
    <parent
      link="fl_calf" />
    <child
      link="fl_foot" />
    <axis
      xyz="0 1 0" />
    <limit
      lower="-12.56"
      upper="12.56"
      effort="10"
      velocity="250" />
  </joint>
  <link
    name="fr_thigh">
    <inertial>
      <origin
        xyz="0.191292819534755 -0.002353194391847 3.05777767527909E-06"
        rpy="0 0 0" />
      <mass
        value="0.32829098650712" />
      <inertia
        ixx="0.000112047683322157"
        ixy="1.62097882949742E-05"
        ixz="-2.09839269870645E-08"
        iyy="0.000847860163744956"
        iyz="5.16343563640244E-10"
        izz="0.000753244083618437" />
    </inertial>
    <visual>
      <origin
        xyz="0 0 0"
        rpy="0 0 0" />
      <geometry>
        <mesh
          filename="package://quad/meshes/fr_thigh.STL" />
      </geometry>
      <material
        name="">
        <color
          rgba="1 1 1 1" />
      </material>
    </visual>
    <collision>
      <origin
        xyz="0 0 0"
        rpy="0 0 0" />
      <geometry>
        <mesh
          filename="package://quad/meshes/fr_thigh.STL" />
      </geometry>
    </collision>
  </link>
  <joint
    name="fr_hip_roll"
    type="revolute">
    <origin
      xyz="0.011 -0.18022 -0.04425"
      rpy="0 0 0" />
    <parent
      link="body" />
    <child
      link="fr_thigh" />
    <axis
      xyz="1 0 0" />
    <limit
      lower="-12.56"
      upper="12.56"
      effort="10"
      velocity="250" />
  </joint>
  <link
    name="fr_calf">
    <inertial>
      <origin
        xyz="2.72389111022342E-06 -0.0780352358767983 -0.0778540126521887"
        rpy="0 0 0" />
      <mass
        value="0.369733221029888" />
      <inertia
        ixx="0.00111379811136972"
        ixy="4.53236441269978E-10"
        ixz="2.08684607912152E-08"
        iyy="0.00120693430900379"
        iyz="-8.65938367597284E-05"
        izz="0.00014562742132654" />
    </inertial>
    <visual>
      <origin
        xyz="0 0 0"
        rpy="0 0 0" />
      <geometry>
        <mesh
          filename="package://quad/meshes/fr_calf.STL" />
      </geometry>
      <material
        name="">
        <color
          rgba="1 1 1 1" />
      </material>
    </visual>
    <collision>
      <origin
        xyz="0 0 0"
        rpy="0 0 0" />
      <geometry>
        <mesh
          filename="package://quad/meshes/fr_calf.STL" />
      </geometry>
    </collision>
  </link>
  <joint
    name="fr_hip_pitch"
    type="revolute">
    <origin
      xyz="0.25125 0.016 0"
      rpy="0 0 0" />
    <parent
      link="fr_thigh" />
    <child
      link="fr_calf" />
    <axis
      xyz="0 -1 0" />
    <limit
      lower="-12.56"
      upper="12.56"
      effort="10"
      velocity="250" />
  </joint>
  <link
    name="fr_foot">
    <inertial>
      <origin
        xyz="-0.00181810973272406 -0.0514205807877514 -0.0990956880947124"
        rpy="0 0 0" />
      <mass
        value="0.113203575524731" />
      <inertia
        ixx="0.000259844925102448"
        ixy="2.8944918948476E-08"
        ixz="2.28109802667943E-06"
        iyy="0.000265395195240856"
        iyz="-4.93150132283772E-06"
        izz="1.44096258097618E-05" />
    </inertial>
    <visual>
      <origin
        xyz="0 0 0"
        rpy="0 0 0" />
      <geometry>
        <mesh
          filename="package://quad/meshes/fr_foot.STL" />
      </geometry>
      <material
        name="">
        <color
          rgba="1 1 1 1" />
      </material>
    </visual>
    <collision>
      <origin
        xyz="0 0 0"
        rpy="0 0 0" />
      <geometry>
        <mesh
          filename="package://quad/meshes/fr_foot.STL" />
      </geometry>
    </collision>
  </link>
  <joint
    name="fr_knee_pitch"
    type="revolute">
    <origin
      xyz="0 -0.063 -0.15625"
      rpy="0 0 0" />
    <parent
      link="fr_calf" />
    <child
      link="fr_foot" />
    <axis
      xyz="0 -1 0" />
    <limit
      lower="-12.56"
      upper="12.56"
      effort="10"
      velocity="250" />
  </joint>
  <link
    name="bl_thigh">
    <inertial>
      <origin
        xyz="-0.191292819512864 0.00235319440921456 3.05778219460151E-06"
        rpy="0 0 0" />
      <mass
        value="0.32829098650712" />
      <inertia
        ixx="0.000112047683322158"
        ixy="1.62097882949869E-05"
        ixz="2.09839269868708E-08"
        iyy="0.000847860163744954"
        iyz="-5.16343562876247E-10"
        izz="0.000753244083618435" />
    </inertial>
    <visual>
      <origin
        xyz="0 0 0"
        rpy="0 0 0" />
      <geometry>
        <mesh
          filename="package://quad/meshes/bl_thigh.STL" />
      </geometry>
      <material
        name="">
        <color
          rgba="1 1 1 1" />
      </material>
    </visual>
    <collision>
      <origin
        xyz="0 0 0"
        rpy="0 0 0" />
      <geometry>
        <mesh
          filename="package://quad/meshes/bl_thigh.STL" />
      </geometry>
    </collision>
  </link>
  <joint
    name="bl_hip_roll"
    type="revolute">
    <origin
      xyz="-0.011 0.055225 -0.04425"
      rpy="0 0 0" />
    <parent
      link="body" />
    <child
      link="bl_thigh" />
    <axis
      xyz="-1 0 0" />
    <limit
      lower="-12.56"
      upper="12.56"
      effort="10"
      velocity="250" />
  </joint>
  <link
    name="bl_calf">
    <inertial>
      <origin
        xyz="-2.72389110878013E-06 0.0780352358767989 -0.0778540126521881"
        rpy="0 0 0" />
      <mass
        value="0.369733221029887" />
      <inertia
        ixx="0.00111379811136972"
        ixy="4.53236442890163E-10"
        ixz="-2.08684607895667E-08"
        iyy="0.00120693430900378"
        iyz="8.65938367597368E-05"
        izz="0.000145627421326541" />
    </inertial>
    <visual>
      <origin
        xyz="0 0 0"
        rpy="0 0 0" />
      <geometry>
        <mesh
          filename="package://quad/meshes/bl_calf.STL" />
      </geometry>
      <material
        name="">
        <color
          rgba="1 1 1 1" />
      </material>
    </visual>
    <collision>
      <origin
        xyz="0 0 0"
        rpy="0 0 0" />
      <geometry>
        <mesh
          filename="package://quad/meshes/bl_calf.STL" />
      </geometry>
    </collision>
  </link>
  <joint
    name="bl_hip_pitch"
    type="revolute">
    <origin
      xyz="-0.25125 -0.016 0"
      rpy="0 0 0" />
    <parent
      link="bl_thigh" />
    <child
      link="bl_calf" />
    <axis
      xyz="0 1 0" />
    <limit
      lower="-12.56"
      upper="12.56"
      effort="10"
      velocity="250" />
  </joint>
  <link
    name="bl_foot">
    <inertial>
      <origin
        xyz="0.00181810973272589 0.0514205807877523 -0.099095688094712"
        rpy="0 0 0" />
      <mass
        value="0.113203575524731" />
      <inertia
        ixx="0.000259844925102448"
        ixy="2.89449189485631E-08"
        ixz="-2.28109802667802E-06"
        iyy="0.000265395195240856"
        iyz="4.93150132283975E-06"
        izz="1.44096258097618E-05" />
    </inertial>
    <visual>
      <origin
        xyz="0 0 0"
        rpy="0 0 0" />
      <geometry>
        <mesh
          filename="package://quad/meshes/bl_foot.STL" />
      </geometry>
      <material
        name="">
        <color
          rgba="1 1 1 1" />
      </material>
    </visual>
    <collision>
      <origin
        xyz="0 0 0"
        rpy="0 0 0" />
      <geometry>
        <mesh
          filename="package://quad/meshes/bl_foot.STL" />
      </geometry>
    </collision>
  </link>
  <joint
    name="bl_knee_pitch"
    type="revolute">
    <origin
      xyz="0 0.063 -0.15625"
      rpy="0 0 0" />
    <parent
      link="bl_calf" />
    <child
      link="bl_foot" />
    <axis
      xyz="0 1 0" />
    <limit
      lower="-12.56"
      upper="12.56"
      effort="10"
      velocity="250" />
  </joint>
  <link
    name="br_thigh">
    <inertial>
      <origin
        xyz="-0.139292819513355 -0.00235319440952178 -3.05778189590294E-06"
        rpy="0 0 0" />
      <mass
        value="0.32829098650712" />
      <inertia
        ixx="0.000112047683322158"
        ixy="-1.62097882949917E-05"
        ixz="-2.09839269872183E-08"
        iyy="0.000847860163744955"
        iyz="-5.16343562904267E-10"
        izz="0.000753244083618437" />
    </inertial>
    <visual>
      <origin
        xyz="0 0 0"
        rpy="0 0 0" />
      <geometry>
        <mesh
          filename="package://quad/meshes/br_thigh.STL" />
      </geometry>
      <material
        name="">
        <color
          rgba="1 1 1 1" />
      </material>
    </visual>
    <collision>
      <origin
        xyz="0 0 0"
        rpy="0 0 0" />
      <geometry>
        <mesh
          filename="package://quad/meshes/br_thigh.STL" />
      </geometry>
    </collision>
  </link>
  <joint
    name="br_hip_roll"
    type="revolute">
    <origin
      xyz="-0.063 -0.18022 -0.04425"
      rpy="0 0 0" />
    <parent
      link="body" />
    <child
      link="br_thigh" />
    <axis
      xyz="1 0 0" />
    <limit
      lower="-12.56"
      upper="12.56"
      effort="10"
      velocity="250" />
  </joint>
  <link
    name="br_calf">
    <inertial>
      <origin
        xyz="2.72389110939075E-06 -0.0780352358767982 -0.0778540126521884"
        rpy="0 0 0" />
      <mass
        value="0.369733221029888" />
      <inertia
        ixx="0.00111379811136972"
        ixy="4.53236442281271E-10"
        ixz="2.08684607900274E-08"
        iyy="0.00120693430900379"
        iyz="-8.65938367597283E-05"
        izz="0.000145627421326539" />
    </inertial>
    <visual>
      <origin
        xyz="0 0 0"
        rpy="0 0 0" />
      <geometry>
        <mesh
          filename="package://quad/meshes/br_calf.STL" />
      </geometry>
      <material
        name="">
        <color
          rgba="1 1 1 1" />
      </material>
    </visual>
    <collision>
      <origin
        xyz="0 0 0"
        rpy="0 0 0" />
      <geometry>
        <mesh
          filename="package://quad/meshes/br_calf.STL" />
      </geometry>
    </collision>
  </link>
  <joint
    name="br_hip_pitch"
    type="revolute">
    <origin
      xyz="-0.19925 0.016 0"
      rpy="0 0 0" />
    <parent
      link="br_thigh" />
    <child
      link="br_calf" />
    <axis
      xyz="0 -1 0" />
    <limit
      lower="-12.56"
      upper="12.56"
      effort="10"
      velocity="250" />
  </joint>
  <link
    name="br_foot">
    <inertial>
      <origin
        xyz="0.00181810973272523 -0.0514205807877515 -0.0990956880947125"
        rpy="0 0 0" />
      <mass
        value="0.113203575524731" />
      <inertia
        ixx="0.000259844925102448"
        ixy="-2.89449189486164E-08"
        ixz="-2.28109802667958E-06"
        iyy="0.000265395195240856"
        iyz="-4.93150132283774E-06"
        izz="1.44096258097617E-05" />
    </inertial>
    <visual>
      <origin
        xyz="0 0 0"
        rpy="0 0 0" />
      <geometry>
        <mesh
          filename="package://quad/meshes/br_foot.STL" />
      </geometry>
      <material
        name="">
        <color
          rgba="1 1 1 1" />
      </material>
    </visual>
    <collision>
      <origin
        xyz="0 0 0"
        rpy="0 0 0" />
      <geometry>
        <mesh
          filename="package://quad/meshes/br_foot.STL" />
      </geometry>
    </collision>
  </link>
  <joint
    name="br_knee_pitch"
    type="revolute">
    <origin
      xyz="0 -0.063 -0.15625"
      rpy="0 0 0" />
    <parent
      link="br_calf" />
    <child
      link="br_foot" />
    <axis
      xyz="0 -1 0" />
    <limit
      lower="-12.56"
      upper="12.56"
      effort="10"
      velocity="250" />
  </joint>
</robot>