<?xml version="1.0" encoding="utf-8"?>
<!-- This URDF was automatically created by SolidWorks to URDF Exporter! Originally created by Stephen Brawner (brawner@gmail.com) 
     Commit Version: 1.6.0-4-g7f85cfe  Build Version: 1.6.7995.38578
     For more information, please see http://wiki.ros.org/sw_urdf_exporter -->
<robot
  name="quad">
  <link
    name="body">
    <inertial>
      <origin
        xyz="-0.327522441191376 -2.92127433354494E-15 1.73127126634753E-06"
        rpy="0 0 0" />
      <mass
        value="2.25128521088266" />
      <inertia
        ixx="0.00576253685191305"
        ixy="-8.73035522282368E-05"
        ixz="1.08167766420804E-18"
        iyy="0.00559133568664286"
        iyz="-1.52694220280297E-18"
        izz="0.00980369773596711" />
    </inertial>
    <visual>
      <origin
        xyz="0 0 0"
        rpy="0 0 0" />
      <geometry>
        <mesh
          filename="package://quad/meshes/body.STL" />
      </geometry>
      <material
        name="">
        <color
          rgba="1 1 1 1" />
      </material>
    </visual>
    <collision>
      <origin
        xyz="0 0 0"
        rpy="0 0 0" />
      <geometry>
        <mesh
          filename="package://quad/meshes/body.STL" />
      </geometry>
    </collision>
  </link>
  <link
    name="fl_thigh">
    <inertial>
      <origin
        xyz="0.11146 0.0015174 -2.6761E-06"
        rpy="0 0 0" />
      <mass
        value="0.37562" />
      <inertia
        ixx="0.00013061"
        ixy="-2.1926E-05"
        ixz="2.1184E-08"
        iyy="0.0014106"
        iyz="4.7747E-10"
        izz="0.0012998" />
    </inertial>
    <visual>
      <origin
        xyz="0 0 0"
        rpy="0 0 0" />
      <geometry>
        <mesh
          filename="package://quad/meshes/fl_thigh.STL" />
      </geometry>
      <material
        name="">
        <color
          rgba="1 1 1 1" />
      </material>
    </visual>
    <collision>
      <origin
        xyz="0 0 0"
        rpy="0 0 0" />
      <geometry>
        <mesh
          filename="package://quad/meshes/fl_thigh.STL" />
      </geometry>
    </collision>
  </link>
  <joint
    name="fl_hip_roll"
    type="revolute">
    <origin
      xyz="-0.214 0.11772 0"
      rpy="0 0 0" />
    <parent
      link="body" />
    <child
      link="fl_thigh" />
    <axis
      xyz="1 0 0" />
    <limit
      lower="-12.56"
      upper="12.56"
      effort="10"
      velocity="250" />
  </joint>
  <link
    name="fl_calf">
    <inertial>
      <origin
        xyz="-2.40445745341988E-06 0.0388018424499711 -0.0964223591973775"
        rpy="0 0 0" />
      <mass
        value="0.41885250755801" />
      <inertia
        ixx="0.00182045970694818"
        ixy="4.00058901888458E-10"
        ixz="-2.1086763888845E-08"
        iyy="0.00192943062173499"
        iyz="0.00011329577878332"
        izz="0.000165412004471573" />
    </inertial>
    <visual>
      <origin
        xyz="0 0 0"
        rpy="0 0 0" />
      <geometry>
        <mesh
          filename="package://quad/meshes/fl_calf.STL" />
      </geometry>
      <material
        name="">
        <color
          rgba="1 1 1 1" />
      </material>
    </visual>
    <collision>
      <origin
        xyz="0 0 0"
        rpy="0 0 0" />
      <geometry>
        <mesh
          filename="package://quad/meshes/fl_calf.STL" />
      </geometry>
    </collision>
  </link>
  <joint
    name="fl_hip_pitch"
    type="revolute">
    <origin
      xyz="0.19225 0.023 0"
      rpy="0 0 0" />
    <parent
      link="fl_thigh" />
    <child
      link="fl_calf" />
    <axis
      xyz="0 1 0" />
    <limit
      lower="-12.56"
      upper="12.56"
      effort="10"
      velocity="250" />
  </joint>
  <link
    name="fl_foot">
    <inertial>
      <origin
        xyz="-0.00148248621300923 -0.0055097231343339 -0.120083874258489"
        rpy="0 0 0" />
      <mass
        value="0.128682263244567" />
      <inertia
        ixx="0.000450269316217515"
        ixy="-3.44384333995568E-08"
        ixz="2.75131565094361E-06"
        iyy="0.00045668990687112"
        iyz="6.18509098395221E-06"
        izz="1.55549486939879E-05" />
    </inertial>
    <visual>
      <origin
        xyz="0 0 0"
        rpy="0 0 0" />
      <geometry>
        <mesh
          filename="package://quad/meshes/fl_foot.STL" />
      </geometry>
      <material
        name="">
        <color
          rgba="1 1 1 1" />
      </material>
    </visual>
    <collision>
      <origin
        xyz="0 0 0"
        rpy="0 0 0" />
      <geometry>
        <mesh
          filename="package://quad/meshes/fl_foot.STL" />
      </geometry>
    </collision>
  </link>
  <joint
    name="fl_knee_pitch"
    type="revolute">
    <origin
      xyz="0 0.081 -0.19625"
      rpy="0 0 0" />
    <parent
      link="fl_calf" />
    <child
      link="fl_foot" />
    <axis
      xyz="0 1 0" />
    <limit
      lower="-12.56"
      upper="12.56"
      effort="10"
      velocity="250" />
  </joint>
  <link
    name="fr_thigh">
    <inertial>
      <origin
        xyz="0.111458241789465 -0.00151741306830402 2.67611392544553E-06"
        rpy="0 0 0" />
      <mass
        value="0.375618459455155" />
      <inertia
        ixx="0.000130612599408191"
        ixy="2.19255581461814E-05"
        ixz="-2.11843061242438E-08"
        iyy="0.00141056527954256"
        iyz="4.7747314611089E-10"
        izz="0.00129979435600257" />
    </inertial>
    <visual>
      <origin
        xyz="0 0 0"
        rpy="0 0 0" />
      <geometry>
        <mesh
          filename="package://quad/meshes/fr_thigh.STL" />
      </geometry>
      <material
        name="">
        <color
          rgba="1 1 1 1" />
      </material>
    </visual>
    <collision>
      <origin
        xyz="0 0 0"
        rpy="0 0 0" />
      <geometry>
        <mesh
          filename="package://quad/meshes/fr_thigh.STL" />
      </geometry>
    </collision>
  </link>
  <joint
    name="fr_hip_roll"
    type="revolute">
    <origin
      xyz="-0.214 -0.11773 0"
      rpy="0 0 0" />
    <parent
      link="body" />
    <child
      link="fr_thigh" />
    <axis
      xyz="-1 0 0" />
    <limit
      lower="-12.56"
      upper="12.56"
      effort="10"
      velocity="250" />
  </joint>
  <link
    name="fr_calf">
    <inertial>
      <origin
        xyz="2.40445745275375E-06 -0.0388018424499714 -0.0964223591973775"
        rpy="0 0 0" />
      <mass
        value="0.41885250755801" />
      <inertia
        ixx="0.00182045970694818"
        ixy="4.00058903439811E-10"
        ixz="2.10867638863003E-08"
        iyy="0.00192943062173499"
        iyz="-0.000113295778783327"
        izz="0.000165412004471574" />
    </inertial>
    <visual>
      <origin
        xyz="0 0 0"
        rpy="0 0 0" />
      <geometry>
        <mesh
          filename="package://quad/meshes/fr_calf.STL" />
      </geometry>
      <material
        name="">
        <color
          rgba="1 1 1 1" />
      </material>
    </visual>
    <collision>
      <origin
        xyz="0 0 0"
        rpy="0 0 0" />
      <geometry>
        <mesh
          filename="package://quad/meshes/fr_calf.STL" />
      </geometry>
    </collision>
  </link>
  <joint
    name="fr_hip_pitch"
    type="revolute">
    <origin
      xyz="0.19225 -0.023 0"
      rpy="0 0 0" />
    <parent
      link="fr_thigh" />
    <child
      link="fr_calf" />
    <axis
      xyz="0 -1 0" />
    <limit
      lower="-12.56"
      upper="12.56"
      effort="10"
      velocity="250" />
  </joint>
  <link
    name="fr_foot">
    <inertial>
      <origin
        xyz="-0.00148248621300995 0.00550972313433351 -0.120083874258489"
        rpy="0 0 0" />
      <mass
        value="0.128682263244566" />
      <inertia
        ixx="0.000450269316217515"
        ixy="3.44384333993272E-08"
        ixz="2.75131565094161E-06"
        iyy="0.00045668990687112"
        iyz="-6.1850909839536E-06"
        izz="1.55549486939879E-05" />
    </inertial>
    <visual>
      <origin
        xyz="0 0 0"
        rpy="0 0 0" />
      <geometry>
        <mesh
          filename="package://quad/meshes/fr_foot.STL" />
      </geometry>
      <material
        name="">
        <color
          rgba="1 1 1 1" />
      </material>
    </visual>
    <collision>
      <origin
        xyz="0 0 0"
        rpy="0 0 0" />
      <geometry>
        <mesh
          filename="package://quad/meshes/fr_foot.STL" />
      </geometry>
    </collision>
  </link>
  <joint
    name="fr_knee_pitch"
    type="revolute">
    <origin
      xyz="0 -0.081 -0.19625"
      rpy="0 0 0" />
    <parent
      link="fr_calf" />
    <child
      link="fr_foot" />
    <axis
      xyz="0 -1 0" />
    <limit
      lower="-12.56"
      upper="12.56"
      effort="10"
      velocity="250" />
  </joint>
  <link
    name="bl_thigh">
    <inertial>
      <origin
        xyz="-0.111458241789465 0.0015174130683049 2.67611392546635E-06"
        rpy="0 0 0" />
      <mass
        value="0.375618459455155" />
      <inertia
        ixx="0.000130612599408191"
        ixy="2.19255581461908E-05"
        ixz="2.11843061246858E-08"
        iyy="0.00141056527954256"
        iyz="-4.77473147105328E-10"
        izz="0.00129979435600256" />
    </inertial>
    <visual>
      <origin
        xyz="0 0 0"
        rpy="0 0 0" />
      <geometry>
        <mesh
          filename="package://quad/meshes/bl_thigh.STL" />
      </geometry>
      <material
        name="">
        <color
          rgba="1 1 1 1" />
      </material>
    </visual>
    <collision>
      <origin
        xyz="0 0 0"
        rpy="0 0 0" />
      <geometry>
        <mesh
          filename="package://quad/meshes/bl_thigh.STL" />
      </geometry>
    </collision>
  </link>
  <joint
    name="bl_hip_roll"
    type="revolute">
    <origin
      xyz="-0.441 0.11772 0"
      rpy="0 0 0" />
    <parent
      link="body" />
    <child
      link="bl_thigh" />
    <axis
      xyz="1 0 0" />
    <limit
      lower="-12.56"
      upper="12.56"
      effort="10"
      velocity="250" />
  </joint>
  <link
    name="bl_calf">
    <inertial>
      <origin
        xyz="-2.40445745264273E-06 0.0388018424499707 -0.0964223591973779"
        rpy="0 0 0" />
      <mass
        value="0.41885250755801" />
      <inertia
        ixx="0.00182045970694818"
        ixy="4.00058904332018E-10"
        ixz="-2.10867638859219E-08"
        iyy="0.00192943062173499"
        iyz="0.00011329577878331"
        izz="0.000165412004471572" />
    </inertial>
    <visual>
      <origin
        xyz="0 0 0"
        rpy="0 0 0" />
      <geometry>
        <mesh
          filename="package://quad/meshes/bl_calf.STL" />
      </geometry>
      <material
        name="">
        <color
          rgba="1 1 1 1" />
      </material>
    </visual>
    <collision>
      <origin
        xyz="0 0 0"
        rpy="0 0 0" />
      <geometry>
        <mesh
          filename="package://quad/meshes/bl_calf.STL" />
      </geometry>
    </collision>
  </link>
  <joint
    name="bl_hip_pitch"
    type="revolute">
    <origin
      xyz="-0.19225 0.023 0"
      rpy="0 0 0" />
    <parent
      link="bl_thigh" />
    <child
      link="bl_calf" />
    <axis
      xyz="0 1 0" />
    <limit
      lower="-12.56"
      upper="12.56"
      effort="10"
      velocity="250" />
  </joint>
  <link
    name="bl_foot">
    <inertial>
      <origin
        xyz="0.00148248621300989 -0.00550972313433445 -0.120083874258489"
        rpy="0 0 0" />
      <mass
        value="0.128682263244567" />
      <inertia
        ixx="0.000450269316217516"
        ixy="3.44384333993527E-08"
        ixz="-2.75131565094139E-06"
        iyy="0.000456689906871121"
        iyz="6.18509098394999E-06"
        izz="1.55549486939877E-05" />
    </inertial>
    <visual>
      <origin
        xyz="0 0 0"
        rpy="0 0 0" />
      <geometry>
        <mesh
          filename="package://quad/meshes/bl_foot.STL" />
      </geometry>
      <material
        name="">
        <color
          rgba="1 1 1 1" />
      </material>
    </visual>
    <collision>
      <origin
        xyz="0 0 0"
        rpy="0 0 0" />
      <geometry>
        <mesh
          filename="package://quad/meshes/bl_foot.STL" />
      </geometry>
    </collision>
  </link>
  <joint
    name="bl_knee_pitch"
    type="revolute">
    <origin
      xyz="0 0.081 -0.19625"
      rpy="0 0 0" />
    <parent
      link="bl_calf" />
    <child
      link="bl_foot" />
    <axis
      xyz="0 1 0" />
    <limit
      lower="-12.56"
      upper="12.56"
      effort="10"
      velocity="250" />
  </joint>
  <link
    name="br_thigh">
    <inertial>
      <origin
        xyz="0 0 0"
        rpy="0 0 0" />
      <mass
        value="0" />
      <inertia
        ixx="0"
        ixy="0"
        ixz="0"
        iyy="0"
        iyz="0"
        izz="0" />
    </inertial>
    <visual>
      <origin
        xyz="0 0 0"
        rpy="0 0 0" />
      <geometry>
        <mesh
          filename="package://quad/meshes/br_thigh.STL" />
      </geometry>
      <material
        name="">
        <color
          rgba="1 1 1 1" />
      </material>
    </visual>
    <collision>
      <origin
        xyz="0 0 0"
        rpy="0 0 0" />
      <geometry>
        <mesh
          filename="package://quad/meshes/br_thigh.STL" />
      </geometry>
    </collision>
  </link>
  <joint
    name="br_hip_roll"
    type="revolute">
    <origin
      xyz="-0.441 -0.11773 0"
      rpy="0 0 0" />
    <parent
      link="body" />
    <child
      link="br_thigh" />
    <axis
      xyz="-1 0 0" />
    <limit
      lower="-12.56"
      upper="12.56"
      effort="10"
      velocity="250" />
  </joint>
  <link
    name="br_calf">
    <inertial>
      <origin
        xyz="2.40445745286477E-06 -0.0388018424499715 -0.0964223591973775"
        rpy="0 0 0" />
      <mass
        value="0.418852507558011" />
      <inertia
        ixx="0.00182045970694818"
        ixy="4.00058903159081E-10"
        ixz="2.1086763886193E-08"
        iyy="0.00192943062173499"
        iyz="-0.000113295778783326"
        izz="0.000165412004471572" />
    </inertial>
    <visual>
      <origin
        xyz="0 0 0"
        rpy="0 0 0" />
      <geometry>
        <mesh
          filename="package://quad/meshes/br_calf.STL" />
      </geometry>
      <material
        name="">
        <color
          rgba="1 1 1 1" />
      </material>
    </visual>
    <collision>
      <origin
        xyz="0 0 0"
        rpy="0 0 0" />
      <geometry>
        <mesh
          filename="package://quad/meshes/br_calf.STL" />
      </geometry>
    </collision>
  </link>
  <joint
    name="br_hip_pitch"
    type="revolute">
    <origin
      xyz="-0.19225 -0.023 0"
      rpy="0 0 0" />
    <parent
      link="br_thigh" />
    <child
      link="br_calf" />
    <axis
      xyz="0 -1 0" />
    <limit
      lower="-12.56"
      upper="12.56"
      effort="10"
      velocity="250" />
  </joint>
  <link
    name="br_foot">
    <inertial>
      <origin
        xyz="0.0014825 0.0055097 -0.12008"
        rpy="0 0 0" />
      <mass
        value="0.12868" />
      <inertia
        ixx="0.00045027"
        ixy="-3.4438E-08"
        ixz="-2.7513E-06"
        iyy="0.00045669"
        iyz="-6.1851E-06"
        izz="1.5555E-05" />
    </inertial>
    <visual>
      <origin
        xyz="0 0 0"
        rpy="0 0 0" />
      <geometry>
        <mesh
          filename="package://quad/meshes/br_foot.STL" />
      </geometry>
      <material
        name="">
        <color
          rgba="1 1 1 1" />
      </material>
    </visual>
    <collision>
      <origin
        xyz="0 0 0"
        rpy="0 0 0" />
      <geometry>
        <mesh
          filename="package://quad/meshes/br_foot.STL" />
      </geometry>
    </collision>
  </link>
  <joint
    name="br_knee_pitch"
    type="revolute">
    <origin
      xyz="0 -0.081 -0.19625"
      rpy="0 0 0" />
    <parent
      link="br_calf" />
    <child
      link="br_foot" />
    <axis
      xyz="0 -1 0" />
    <limit
      lower="-12.56"
      upper="12.56"
      effort="10"
      velocity="250" />
  </joint>
</robot>