<?xml version="1.0" ?>
<!-- =================================================================================== -->
<!-- |    This document was autogenerated by xacro from basic_quad.urdf.xacro          | -->
<!-- |    EDITING THIS FILE BY HAND IS NOT RECOMMENDED                                 | -->
<!-- =================================================================================== -->
<robot name="basic_quad">
  <!-- Actual URDF Definitions -->
  <link name="body">
    <visual>
      <origin rpy="0 0 0" xyz="0.0 0.0 0.0"/>
      <geometry>
        <box size="0.7 0.25145 0.05"/>
      </geometry>
      <material name="blue">
        <color rgba="0 0 1 1"/>
      </material>
    </visual>
  </link>
  <link name="fl_thigh">
    <visual>
      <origin rpy="0 0 0" xyz="0.11275 0.0 0.0"/>
      <geometry>
        <box size="0.2255 0.05 0.05"/>
      </geometry>
      <material name="blue">
        <color rgba="0 0 1 1"/>
      </material>
    </visual>
  </link>
  <link name="fl_calf">
    <visual>
      <origin rpy="0 0 0" xyz="0.0 0.0 -0.098125"/>
      <geometry>
        <box size="0.05 0.05 0.19625"/>
      </geometry>
      <material name="blue">
        <color rgba="0 0 1 1"/>
      </material>
    </visual>
  </link>
  <link name="fl_foot">
    <visual>
      <origin rpy="0 0 0" xyz="0.0 0.0 -0.07"/>
      <geometry>
        <box size="0.05 0.05 0.14"/>
      </geometry>
      <material name="blue">
        <color rgba="0 0 1 1"/>
      </material>
    </visual>
  </link>
  <joint name="fl_hip_roll" type="revolute">
    <parent link="body"/>
    <child link="fl_thigh"/>
    <origin rpy="0 0 0" xyz="0.12449999999999997 0.125725 0.0"/>
    <axis xyz="1 0 0"/>
    <limit effort="1" lower="-3.14" upper="3.14" velocity="1"/>
  </joint>
  <joint name="fl_hip_pitch" type="revolute">
    <parent link="fl_thigh"/>
    <child link="fl_calf"/>
    <origin rpy="0 0 0" xyz="0.2255 0.023 0.0"/>
    <axis xyz="0 1 0"/>
    <limit effort="1" lower="-3.14" upper="3.14" velocity="1"/>
  </joint>
  <joint name="fl_knee_pitch" type="revolute">
    <parent link="fl_calf"/>
    <child link="fl_foot"/>
    <origin rpy="0 0 0" xyz="0.0 0.063 -0.19625"/>
    <axis xyz="0 1 0"/>
    <limit effort="1" lower="-3.14" upper="3.14" velocity="1"/>
  </joint>
  <link name="fr_thigh">
    <visual>
      <origin rpy="0 0 0" xyz="0.11275 0.0 0.0"/>
      <geometry>
        <box size="0.2255 0.05 0.05"/>
      </geometry>
      <material name="blue">
        <color rgba="0 0 1 1"/>
      </material>
    </visual>
  </link>
  <link name="fr_calf">
    <visual>
      <origin rpy="0 0 0" xyz="0.0 0.0 -0.098125"/>
      <geometry>
        <box size="0.05 0.05 0.19625"/>
      </geometry>
      <material name="blue">
        <color rgba="0 0 1 1"/>
      </material>
    </visual>
  </link>
  <link name="fr_foot">
    <visual>
      <origin rpy="0 0 0" xyz="0.0 0.0 -0.07"/>
      <geometry>
        <box size="0.05 0.05 0.14"/>
      </geometry>
      <material name="blue">
        <color rgba="0 0 1 1"/>
      </material>
    </visual>
  </link>
  <joint name="fr_hip_roll" type="revolute">
    <parent link="body"/>
    <child link="fr_thigh"/>
    <origin rpy="0 0 0" xyz="0.12449999999999997 -0.125725 0.0"/>
    <axis xyz="1 0 0"/>
    <limit effort="1" lower="-3.14" upper="3.14" velocity="1"/>
  </joint>
  <joint name="fr_hip_pitch" type="revolute">
    <parent link="fr_thigh"/>
    <child link="fr_calf"/>
    <origin rpy="0 0 0" xyz="0.2255 -0.023 0.0"/>
    <axis xyz="0 -1 0"/>
    <limit effort="1" lower="-3.14" upper="3.14" velocity="1"/>
  </joint>
  <joint name="fr_knee_pitch" type="revolute">
    <parent link="fr_calf"/>
    <child link="fr_foot"/>
    <origin rpy="0 0 0" xyz="0.0 -0.063 -0.19625"/>
    <axis xyz="0 -1 0"/>
    <limit effort="1" lower="-3.14" upper="3.14" velocity="1"/>
  </joint>
  <link name="bl_thigh">
    <visual>
      <origin rpy="0 0 0" xyz="-0.11275 0.0 0.0"/>
      <geometry>
        <box size="0.2255 0.05 0.05"/>
      </geometry>
      <material name="blue">
        <color rgba="0 0 1 1"/>
      </material>
    </visual>
  </link>
  <link name="bl_calf">
    <visual>
      <origin rpy="0 0 0" xyz="0.0 0.0 -0.098125"/>
      <geometry>
        <box size="0.05 0.05 0.19625"/>
      </geometry>
      <material name="blue">
        <color rgba="0 0 1 1"/>
      </material>
    </visual>
  </link>
  <link name="bl_foot">
    <visual>
      <origin rpy="0 0 0" xyz="0.0 0.0 -0.07"/>
      <geometry>
        <box size="0.05 0.05 0.14"/>
      </geometry>
      <material name="blue">
        <color rgba="0 0 1 1"/>
      </material>
    </visual>
  </link>
  <joint name="bl_hip_roll" type="revolute">
    <parent link="body"/>
    <child link="bl_thigh"/>
    <origin rpy="0 0 0" xyz="-0.12449999999999997 0.125725 0.0"/>
    <axis xyz="-1 0 0"/>
    <limit effort="1" lower="-3.14" upper="3.14" velocity="1"/>
  </joint>
  <joint name="bl_hip_pitch" type="revolute">
    <parent link="bl_thigh"/>
    <child link="bl_calf"/>
    <origin rpy="0 0 0" xyz="-0.2255 0.023 0.0"/>
    <axis xyz="0 1 0"/>
    <limit effort="1" lower="-3.14" upper="3.14" velocity="1"/>
  </joint>
  <joint name="bl_knee_pitch" type="revolute">
    <parent link="bl_calf"/>
    <child link="bl_foot"/>
    <origin rpy="0 0 0" xyz="0.0 0.063 -0.19625"/>
    <axis xyz="0 1 0"/>
    <limit effort="1" lower="-3.14" upper="3.14" velocity="1"/>
  </joint>
  <link name="br_thigh">
    <visual>
      <origin rpy="0 0 0" xyz="-0.11275 0.0 0.0"/>
      <geometry>
        <box size="0.2255 0.05 0.05"/>
      </geometry>
      <material name="blue">
        <color rgba="0 0 1 1"/>
      </material>
    </visual>
  </link>
  <link name="br_calf">
    <visual>
      <origin rpy="0 0 0" xyz="0.0 0.0 -0.098125"/>
      <geometry>
        <box size="0.05 0.05 0.19625"/>
      </geometry>
      <material name="blue">
        <color rgba="0 0 1 1"/>
      </material>
    </visual>
  </link>
  <link name="br_foot">
    <visual>
      <origin rpy="0 0 0" xyz="0.0 0.0 -0.07"/>
      <geometry>
        <box size="0.05 0.05 0.14"/>
      </geometry>
      <material name="blue">
        <color rgba="0 0 1 1"/>
      </material>
    </visual>
  </link>
  <joint name="br_hip_roll" type="revolute">
    <parent link="body"/>
    <child link="br_thigh"/>
    <origin rpy="0 0 0" xyz="-0.12449999999999997 -0.125725 0.0"/>
    <axis xyz="-1 0 0"/>
    <limit effort="1" lower="-3.14" upper="3.14" velocity="1"/>
  </joint>
  <joint name="br_hip_pitch" type="revolute">
    <parent link="br_thigh"/>
    <child link="br_calf"/>
    <origin rpy="0 0 0" xyz="-0.2255 -0.023 0.0"/>
    <axis xyz="0 -1 0"/>
    <limit effort="1" lower="-3.14" upper="3.14" velocity="1"/>
  </joint>
  <joint name="br_knee_pitch" type="revolute">
    <parent link="br_calf"/>
    <child link="br_foot"/>
    <origin rpy="0 0 0" xyz="0.0 -0.063 -0.19625"/>
    <axis xyz="0 -1 0"/>
    <limit effort="1" lower="-3.14" upper="3.14" velocity="1"/>
  </joint>
</robot>
